2020-04-27 14:58:08,039 - telegram.ext.updater - ERROR - Error while getting Updates: Conflict: terminated by other getUpdates request; make sure that only one bot instance is running
2020-04-27 14:58:08,040 - telegram.ext.dispatcher - ERROR - No error handlers are registered, logging exception.
Traceback (most recent call last):
  File "/var/www/venv/lib64/python3.6/site-packages/telegram/ext/updater.py", line 380, in _network_loop_retry
    if not action_cb():
  File "/var/www/venv/lib64/python3.6/site-packages/telegram/ext/updater.py", line 341, in polling_action_cb
    allowed_updates=allowed_updates)
  File "<decorator-gen-31>", line 2, in get_updates
  File "/var/www/venv/lib64/python3.6/site-packages/telegram/bot.py", line 70, in decorator
    result = func(*args, **kwargs)
  File "/var/www/venv/lib64/python3.6/site-packages/telegram/bot.py", line 2136, in get_updates
    result = self._request.post(url, data, timeout=float(read_latency) + float(timeout))
  File "/var/www/venv/lib64/python3.6/site-packages/telegram/utils/request.py", line 334, in post
    **urlopen_kwargs)
  File "/var/www/venv/lib64/python3.6/site-packages/telegram/utils/request.py", line 249, in _request_wrapper
    raise Conflict(message)
telegram.error.Conflict: Conflict: terminated by other getUpdates request; make sure that only one bot instance is running
2020-04-27 14:58:13,735 - telegram.ext.updater - ERROR - Error while getting Updates: Conflict: terminated by other getUpdates request; make sure that only one bot instance is running
2020-04-27 14:58:13,736 - telegram.ext.dispatcher - ERROR - No error handlers are registered, logging exception.
Traceback (most recent call last):
  File "/var/www/venv/lib64/python3.6/site-packages/telegram/ext/updater.py", line 380, in _network_loop_retry
    if not action_cb():
  File "/var/www/venv/lib64/python3.6/site-packages/telegram/ext/updater.py", line 341, in polling_action_cb
    allowed_updates=allowed_updates)
  File "<decorator-gen-31>", line 2, in get_updates
  File "/var/www/venv/lib64/python3.6/site-packages/telegram/bot.py", line 70, in decorator
    result = func(*args, **kwargs)
  File "/var/www/venv/lib64/python3.6/site-packages/telegram/bot.py", line 2136, in get_updates
    result = self._request.post(url, data, timeout=float(read_latency) + float(timeout))
  File "/var/www/venv/lib64/python3.6/site-packages/telegram/utils/request.py", line 334, in post
    **urlopen_kwargs)
  File "/var/www/venv/lib64/python3.6/site-packages/telegram/utils/request.py", line 249, in _request_wrapper
    raise Conflict(message)
telegram.error.Conflict: Conflict: terminated by other getUpdates request; make sure that only one bot instance is running
2020-04-27 14:58:20,683 - telegram.ext.updater - ERROR - Error while getting Updates: Conflict: terminated by other getUpdates request; make sure that only one bot instance is running
2020-04-27 14:58:20,683 - telegram.ext.dispatcher - ERROR - No error handlers are registered, logging exception.
Traceback (most recent call last):
  File "/var/www/venv/lib64/python3.6/site-packages/telegram/ext/updater.py", line 380, in _network_loop_retry
    if not action_cb():
  File "/var/www/venv/lib64/python3.6/site-packages/telegram/ext/updater.py", line 341, in polling_action_cb
    allowed_updates=allowed_updates)
  File "<decorator-gen-31>", line 2, in get_updates
  File "/var/www/venv/lib64/python3.6/site-packages/telegram/bot.py", line 70, in decorator
    result = func(*args, **kwargs)
  File "/var/www/venv/lib64/python3.6/site-packages/telegram/bot.py", line 2136, in get_updates
    result = self._request.post(url, data, timeout=float(read_latency) + float(timeout))
  File "/var/www/venv/lib64/python3.6/site-packages/telegram/utils/request.py", line 334, in post
    **urlopen_kwargs)
  File "/var/www/venv/lib64/python3.6/site-packages/telegram/utils/request.py", line 249, in _request_wrapper
    raise Conflict(message)
telegram.error.Conflict: Conflict: terminated by other getUpdates request; make sure that only one bot instance is running
2020-04-27 14:58:26,503 - telegram.ext.updater - ERROR - Error while getting Updates: Conflict: terminated by other getUpdates request; make sure that only one bot instance is running
2020-04-27 14:58:26,503 - telegram.ext.dispatcher - ERROR - No error handlers are registered, logging exception.
Traceback (most recent call last):
  File "/var/www/venv/lib64/python3.6/site-packages/telegram/ext/updater.py", line 380, in _network_loop_retry
    if not action_cb():
  File "/var/www/venv/lib64/python3.6/site-packages/telegram/ext/updater.py", line 341, in polling_action_cb
    allowed_updates=allowed_updates)
  File "<decorator-gen-31>", line 2, in get_updates
  File "/var/www/venv/lib64/python3.6/site-packages/telegram/bot.py", line 70, in decorator
    result = func(*args, **kwargs)
  File "/var/www/venv/lib64/python3.6/site-packages/telegram/bot.py", line 2136, in get_updates
    result = self._request.post(url, data, timeout=float(read_latency) + float(timeout))
  File "/var/www/venv/lib64/python3.6/site-packages/telegram/utils/request.py", line 334, in post
    **urlopen_kwargs)
  File "/var/www/venv/lib64/python3.6/site-packages/telegram/utils/request.py", line 249, in _request_wrapper
    raise Conflict(message)
telegram.error.Conflict: Conflict: terminated by other getUpdates request; make sure that only one bot instance is running
2020-04-27 14:58:31,242 - Logic.Commands - INFO - User 383327735: ask Terms;
2020-04-27 14:58:34,073 - telegram.ext.updater - ERROR - Error while getting Updates: Conflict: terminated by other getUpdates request; make sure that only one bot instance is running
2020-04-27 14:58:34,073 - telegram.ext.dispatcher - ERROR - No error handlers are registered, logging exception.
Traceback (most recent call last):
  File "/var/www/venv/lib64/python3.6/site-packages/telegram/ext/updater.py", line 380, in _network_loop_retry
    if not action_cb():
  File "/var/www/venv/lib64/python3.6/site-packages/telegram/ext/updater.py", line 341, in polling_action_cb
    allowed_updates=allowed_updates)
  File "<decorator-gen-31>", line 2, in get_updates
  File "/var/www/venv/lib64/python3.6/site-packages/telegram/bot.py", line 70, in decorator
    result = func(*args, **kwargs)
  File "/var/www/venv/lib64/python3.6/site-packages/telegram/bot.py", line 2136, in get_updates
    result = self._request.post(url, data, timeout=float(read_latency) + float(timeout))
  File "/var/www/venv/lib64/python3.6/site-packages/telegram/utils/request.py", line 334, in post
    **urlopen_kwargs)
  File "/var/www/venv/lib64/python3.6/site-packages/telegram/utils/request.py", line 249, in _request_wrapper
    raise Conflict(message)
telegram.error.Conflict: Conflict: terminated by other getUpdates request; make sure that only one bot instance is running
2020-04-27 14:58:39,765 - telegram.ext.updater - ERROR - Error while getting Updates: Conflict: terminated by other getUpdates request; make sure that only one bot instance is running
2020-04-27 14:58:39,765 - telegram.ext.dispatcher - ERROR - No error handlers are registered, logging exception.
Traceback (most recent call last):
  File "/var/www/venv/lib64/python3.6/site-packages/telegram/ext/updater.py", line 380, in _network_loop_retry
    if not action_cb():
  File "/var/www/venv/lib64/python3.6/site-packages/telegram/ext/updater.py", line 341, in polling_action_cb
    allowed_updates=allowed_updates)
  File "<decorator-gen-31>", line 2, in get_updates
  File "/var/www/venv/lib64/python3.6/site-packages/telegram/bot.py", line 70, in decorator
    result = func(*args, **kwargs)
  File "/var/www/venv/lib64/python3.6/site-packages/telegram/bot.py", line 2136, in get_updates
    result = self._request.post(url, data, timeout=float(read_latency) + float(timeout))
  File "/var/www/venv/lib64/python3.6/site-packages/telegram/utils/request.py", line 334, in post
    **urlopen_kwargs)
  File "/var/www/venv/lib64/python3.6/site-packages/telegram/utils/request.py", line 249, in _request_wrapper
    raise Conflict(message)
telegram.error.Conflict: Conflict: terminated by other getUpdates request; make sure that only one bot instance is running
2020-04-27 14:58:46,710 - telegram.ext.updater - ERROR - Error while getting Updates: Conflict: terminated by other getUpdates request; make sure that only one bot instance is running
2020-04-27 14:58:46,710 - telegram.ext.dispatcher - ERROR - No error handlers are registered, logging exception.
Traceback (most recent call last):
  File "/var/www/venv/lib64/python3.6/site-packages/telegram/ext/updater.py", line 380, in _network_loop_retry
    if not action_cb():
  File "/var/www/venv/lib64/python3.6/site-packages/telegram/ext/updater.py", line 341, in polling_action_cb
    allowed_updates=allowed_updates)
  File "<decorator-gen-31>", line 2, in get_updates
  File "/var/www/venv/lib64/python3.6/site-packages/telegram/bot.py", line 70, in decorator
    result = func(*args, **kwargs)
  File "/var/www/venv/lib64/python3.6/site-packages/telegram/bot.py", line 2136, in get_updates
    result = self._request.post(url, data, timeout=float(read_latency) + float(timeout))
  File "/var/www/venv/lib64/python3.6/site-packages/telegram/utils/request.py", line 334, in post
    **urlopen_kwargs)
  File "/var/www/venv/lib64/python3.6/site-packages/telegram/utils/request.py", line 249, in _request_wrapper
    raise Conflict(message)
telegram.error.Conflict: Conflict: terminated by other getUpdates request; make sure that only one bot instance is running
2020-04-27 14:58:52,531 - telegram.ext.updater - ERROR - Error while getting Updates: Conflict: terminated by other getUpdates request; make sure that only one bot instance is running
2020-04-27 14:58:52,531 - telegram.ext.dispatcher - ERROR - No error handlers are registered, logging exception.
Traceback (most recent call last):
  File "/var/www/venv/lib64/python3.6/site-packages/telegram/ext/updater.py", line 380, in _network_loop_retry
    if not action_cb():
  File "/var/www/venv/lib64/python3.6/site-packages/telegram/ext/updater.py", line 341, in polling_action_cb
    allowed_updates=allowed_updates)
  File "<decorator-gen-31>", line 2, in get_updates
  File "/var/www/venv/lib64/python3.6/site-packages/telegram/bot.py", line 70, in decorator
    result = func(*args, **kwargs)
  File "/var/www/venv/lib64/python3.6/site-packages/telegram/bot.py", line 2136, in get_updates
    result = self._request.post(url, data, timeout=float(read_latency) + float(timeout))
  File "/var/www/venv/lib64/python3.6/site-packages/telegram/utils/request.py", line 334, in post
    **urlopen_kwargs)
  File "/var/www/venv/lib64/python3.6/site-packages/telegram/utils/request.py", line 249, in _request_wrapper
    raise Conflict(message)
telegram.error.Conflict: Conflict: terminated by other getUpdates request; make sure that only one bot instance is running
2020-04-27 14:59:01,168 - telegram.ext.updater - ERROR - Error while getting Updates: Conflict: terminated by other getUpdates request; make sure that only one bot instance is running
2020-04-27 14:59:01,168 - telegram.ext.dispatcher - ERROR - No error handlers are registered, logging exception.
Traceback (most recent call last):
  File "/var/www/venv/lib64/python3.6/site-packages/telegram/ext/updater.py", line 380, in _network_loop_retry
    if not action_cb():
  File "/var/www/venv/lib64/python3.6/site-packages/telegram/ext/updater.py", line 341, in polling_action_cb
    allowed_updates=allowed_updates)
  File "<decorator-gen-31>", line 2, in get_updates
  File "/var/www/venv/lib64/python3.6/site-packages/telegram/bot.py", line 70, in decorator
    result = func(*args, **kwargs)
  File "/var/www/venv/lib64/python3.6/site-packages/telegram/bot.py", line 2136, in get_updates
    result = self._request.post(url, data, timeout=float(read_latency) + float(timeout))
  File "/var/www/venv/lib64/python3.6/site-packages/telegram/utils/request.py", line 334, in post
    **urlopen_kwargs)
  File "/var/www/venv/lib64/python3.6/site-packages/telegram/utils/request.py", line 249, in _request_wrapper
    raise Conflict(message)
telegram.error.Conflict: Conflict: terminated by other getUpdates request; make sure that only one bot instance is running
2020-04-27 14:59:14,028 - telegram.ext.updater - ERROR - Error while getting Updates: Conflict: terminated by other getUpdates request; make sure that only one bot instance is running
2020-04-27 14:59:14,028 - telegram.ext.dispatcher - ERROR - No error handlers are registered, logging exception.
Traceback (most recent call last):
  File "/var/www/venv/lib64/python3.6/site-packages/telegram/ext/updater.py", line 380, in _network_loop_retry
    if not action_cb():
  File "/var/www/venv/lib64/python3.6/site-packages/telegram/ext/updater.py", line 341, in polling_action_cb
    allowed_updates=allowed_updates)
  File "<decorator-gen-31>", line 2, in get_updates
  File "/var/www/venv/lib64/python3.6/site-packages/telegram/bot.py", line 70, in decorator
    result = func(*args, **kwargs)
  File "/var/www/venv/lib64/python3.6/site-packages/telegram/bot.py", line 2136, in get_updates
    result = self._request.post(url, data, timeout=float(read_latency) + float(timeout))
  File "/var/www/venv/lib64/python3.6/site-packages/telegram/utils/request.py", line 334, in post
    **urlopen_kwargs)
  File "/var/www/venv/lib64/python3.6/site-packages/telegram/utils/request.py", line 249, in _request_wrapper
    raise Conflict(message)
telegram.error.Conflict: Conflict: terminated by other getUpdates request; make sure that only one bot instance is running
2020-04-27 14:59:33,219 - telegram.ext.updater - ERROR - Error while getting Updates: Conflict: terminated by other getUpdates request; make sure that only one bot instance is running
2020-04-27 14:59:33,219 - telegram.ext.dispatcher - ERROR - No error handlers are registered, logging exception.
Traceback (most recent call last):
  File "/var/www/venv/lib64/python3.6/site-packages/telegram/ext/updater.py", line 380, in _network_loop_retry
    if not action_cb():
  File "/var/www/venv/lib64/python3.6/site-packages/telegram/ext/updater.py", line 341, in polling_action_cb
    allowed_updates=allowed_updates)
  File "<decorator-gen-31>", line 2, in get_updates
  File "/var/www/venv/lib64/python3.6/site-packages/telegram/bot.py", line 70, in decorator
    result = func(*args, **kwargs)
  File "/var/www/venv/lib64/python3.6/site-packages/telegram/bot.py", line 2136, in get_updates
    result = self._request.post(url, data, timeout=float(read_latency) + float(timeout))
  File "/var/www/venv/lib64/python3.6/site-packages/telegram/utils/request.py", line 334, in post
    **urlopen_kwargs)
  File "/var/www/venv/lib64/python3.6/site-packages/telegram/utils/request.py", line 249, in _request_wrapper
    raise Conflict(message)
telegram.error.Conflict: Conflict: terminated by other getUpdates request; make sure that only one bot instance is running
2020-04-27 14:59:54,513 - telegram.ext.updater - ERROR - Error while getting Updates: Conflict: terminated by other getUpdates request; make sure that only one bot instance is running
2020-04-27 14:59:54,513 - telegram.ext.dispatcher - ERROR - No error handlers are registered, logging exception.
Traceback (most recent call last):
  File "/var/www/venv/lib64/python3.6/site-packages/telegram/ext/updater.py", line 380, in _network_loop_retry
    if not action_cb():
  File "/var/www/venv/lib64/python3.6/site-packages/telegram/ext/updater.py", line 341, in polling_action_cb
    allowed_updates=allowed_updates)
  File "<decorator-gen-31>", line 2, in get_updates
  File "/var/www/venv/lib64/python3.6/site-packages/telegram/bot.py", line 70, in decorator
    result = func(*args, **kwargs)
  File "/var/www/venv/lib64/python3.6/site-packages/telegram/bot.py", line 2136, in get_updates
    result = self._request.post(url, data, timeout=float(read_latency) + float(timeout))
  File "/var/www/venv/lib64/python3.6/site-packages/telegram/utils/request.py", line 334, in post
    **urlopen_kwargs)
  File "/var/www/venv/lib64/python3.6/site-packages/telegram/utils/request.py", line 249, in _request_wrapper
    raise Conflict(message)
telegram.error.Conflict: Conflict: terminated by other getUpdates request; make sure that only one bot instance is running
2020-04-27 15:00:24,346 - telegram.ext.updater - ERROR - Error while getting Updates: Conflict: terminated by other getUpdates request; make sure that only one bot instance is running
2020-04-27 15:00:24,346 - telegram.ext.dispatcher - ERROR - No error handlers are registered, logging exception.
Traceback (most recent call last):
  File "/var/www/venv/lib64/python3.6/site-packages/telegram/ext/updater.py", line 380, in _network_loop_retry
    if not action_cb():
  File "/var/www/venv/lib64/python3.6/site-packages/telegram/ext/updater.py", line 341, in polling_action_cb
    allowed_updates=allowed_updates)
  File "<decorator-gen-31>", line 2, in get_updates
  File "/var/www/venv/lib64/python3.6/site-packages/telegram/bot.py", line 70, in decorator
    result = func(*args, **kwargs)
  File "/var/www/venv/lib64/python3.6/site-packages/telegram/bot.py", line 2136, in get_updates
    result = self._request.post(url, data, timeout=float(read_latency) + float(timeout))
  File "/var/www/venv/lib64/python3.6/site-packages/telegram/utils/request.py", line 334, in post
    **urlopen_kwargs)
  File "/var/www/venv/lib64/python3.6/site-packages/telegram/utils/request.py", line 249, in _request_wrapper
    raise Conflict(message)
telegram.error.Conflict: Conflict: terminated by other getUpdates request; make sure that only one bot instance is running
2020-04-27 15:01:06,994 - telegram.ext.updater - ERROR - Error while getting Updates: Conflict: terminated by other getUpdates request; make sure that only one bot instance is running
2020-04-27 15:01:06,994 - telegram.ext.dispatcher - ERROR - No error handlers are registered, logging exception.
Traceback (most recent call last):
  File "/var/www/venv/lib64/python3.6/site-packages/telegram/ext/updater.py", line 380, in _network_loop_retry
    if not action_cb():
  File "/var/www/venv/lib64/python3.6/site-packages/telegram/ext/updater.py", line 341, in polling_action_cb
    allowed_updates=allowed_updates)
  File "<decorator-gen-31>", line 2, in get_updates
  File "/var/www/venv/lib64/python3.6/site-packages/telegram/bot.py", line 70, in decorator
    result = func(*args, **kwargs)
  File "/var/www/venv/lib64/python3.6/site-packages/telegram/bot.py", line 2136, in get_updates
    result = self._request.post(url, data, timeout=float(read_latency) + float(timeout))
  File "/var/www/venv/lib64/python3.6/site-packages/telegram/utils/request.py", line 334, in post
    **urlopen_kwargs)
  File "/var/www/venv/lib64/python3.6/site-packages/telegram/utils/request.py", line 249, in _request_wrapper
    raise Conflict(message)
telegram.error.Conflict: Conflict: terminated by other getUpdates request; make sure that only one bot instance is running
2020-04-27 15:09:44,838 - Logic.Commands - INFO - User 383327735: ask Terms;
2020-04-27 15:17:41,635 - Logic.Commands - INFO - User 415927712: send /start command;
2020-04-27 15:17:43,364 - telegram.ext.dispatcher - ERROR - No error handlers are registered, logging exception.
Traceback (most recent call last):
  File "/var/www/venv/lib64/python3.6/site-packages/telegram/ext/dispatcher.py", line 343, in process_update
    handler.handle_update(update, self, check, context)
  File "/var/www/venv/lib64/python3.6/site-packages/telegram/ext/handler.py", line 117, in handle_update
    return self.callback(update, context)
  File "/var/www/parent-bot/src/Logic/Commands.py", line 50, in demo
    video=open("src/Logic/img/demo.mp4", "rb"),
FileNotFoundError: [Errno 2] No such file or directory: 'src/Logic/img/demo.mp4'
2020-04-27 16:20:41,059 - Logic.Commands - INFO - User 917453253: send /start command;
2020-04-27 16:28:39,744 - Logic.Commands - INFO - User 415927712: send /start command;
2020-04-27 16:28:41,185 - telegram.ext.dispatcher - ERROR - No error handlers are registered, logging exception.
Traceback (most recent call last):
  File "/var/www/venv/lib64/python3.6/site-packages/telegram/ext/dispatcher.py", line 343, in process_update
    handler.handle_update(update, self, check, context)
  File "/var/www/venv/lib64/python3.6/site-packages/telegram/ext/handler.py", line 117, in handle_update
    return self.callback(update, context)
  File "/var/www/parent-bot/src/Logic/Commands.py", line 50, in demo
    video=open("src/Logic/img/demo.mp4", "rb"),
FileNotFoundError: [Errno 2] No such file or directory: 'src/Logic/img/demo.mp4'
2020-04-28 09:30:16,363 - Logic.Commands - INFO - User 415927712: send /start command;
2020-04-28 09:30:18,309 - Logic.Payment - INFO - User 415927712: genetare link to subscribe - http://tinyurl.com/ycu74m4e;
2020-04-28 09:30:22,159 - Logic.Commands - INFO - User 415927712: ask Terms;
2020-04-28 09:32:50,467 - telegram.ext.dispatcher - ERROR - No error handlers are registered, logging exception.
Traceback (most recent call last):
  File "/var/www/venv/lib64/python3.6/site-packages/telegram/ext/dispatcher.py", line 343, in process_update
    handler.handle_update(update, self, check, context)
  File "/var/www/venv/lib64/python3.6/site-packages/telegram/ext/handler.py", line 117, in handle_update
    return self.callback(update, context)
  File "/var/www/parent-bot/src/Logic/Commands.py", line 50, in demo
    video=open("src/Logic/img/demo.mp4", "rb"),
FileNotFoundError: [Errno 2] No such file or directory: 'src/Logic/img/demo.mp4'
2020-04-28 09:33:09,783 - Logic.Commands - INFO - User 275157861: send /start command;
2020-04-28 09:33:11,551 - Logic.Payment - INFO - User 275157861: genetare link to subscribe - http://tinyurl.com/yb2mwfjo;
2020-04-28 09:33:14,504 - Logic.Commands - INFO - User 275157861: ask Terms;
2020-04-28 09:33:59,091 - Logic.Commands - INFO - User 415927712: send /start command;
2020-04-28 09:34:23,910 - Logic.Commands - INFO - User 275157861: send /start command;
2020-04-28 09:34:38,130 - Logic.Commands - INFO - User 275157861: send /start command;
2020-04-28 09:34:40,339 - Logic.Payment - INFO - User 275157861: genetare link to subscribe - http://tinyurl.com/ybjcrflk;
2020-04-28 09:34:59,797 - Logic.Commands - INFO - User 415927712: send /start command;
2020-04-28 09:35:02,088 - telegram.ext.dispatcher - ERROR - No error handlers are registered, logging exception.
Traceback (most recent call last):
  File "/var/www/venv/lib64/python3.6/site-packages/telegram/ext/dispatcher.py", line 343, in process_update
    handler.handle_update(update, self, check, context)
  File "/var/www/venv/lib64/python3.6/site-packages/telegram/ext/handler.py", line 117, in handle_update
    return self.callback(update, context)
  File "/var/www/parent-bot/src/Logic/Commands.py", line 50, in demo
    video=open("src/Logic/img/demo.mp4", "rb"),
FileNotFoundError: [Errno 2] No such file or directory: 'src/Logic/img/demo.mp4'
2020-04-28 09:36:18,557 - Logic.Commands - INFO - User 415927712: send /start command;
2020-04-28 09:36:20,287 - telegram.ext.dispatcher - ERROR - No error handlers are registered, logging exception.
Traceback (most recent call last):
  File "/var/www/venv/lib64/python3.6/site-packages/telegram/ext/dispatcher.py", line 343, in process_update
    handler.handle_update(update, self, check, context)
  File "/var/www/venv/lib64/python3.6/site-packages/telegram/ext/handler.py", line 117, in handle_update
    return self.callback(update, context)
  File "/var/www/parent-bot/src/Logic/Commands.py", line 50, in demo
    video=open("src/Logic/img/demo.mp4", "rb"),
FileNotFoundError: [Errno 2] No such file or directory: 'src/Logic/img/demo.mp4'
2020-04-28 15:05:04,969 - Logic.Commands - INFO - User 275157861: send /start command;
2020-04-28 15:09:12,410 - Logic.Payment - INFO - User 275157861: genetare link to subscribe - http://tinyurl.com/y8eorprw;
2020-04-28 15:10:42,455 - Logic.Commands - INFO - User 275157861: send /start command;
2020-04-28 15:14:49,935 - Logic.Commands - INFO - User 275157861: send /start command;
2020-04-28 15:48:36,989 - Logic.Commands - INFO - User 383327735: send /start command;
2020-04-28 15:48:40,602 - telegram.ext.dispatcher - ERROR - No error handlers are registered, logging exception.
Traceback (most recent call last):
  File "/var/www/venv/lib64/python3.6/site-packages/telegram/ext/dispatcher.py", line 343, in process_update
    handler.handle_update(update, self, check, context)
  File "/var/www/venv/lib64/python3.6/site-packages/telegram/ext/handler.py", line 117, in handle_update
    return self.callback(update, context)
  File "/var/www/parent-bot/src/Logic/Commands.py", line 50, in demo
    video=open("src/Logic/img/demo.mp4", "rb"),
FileNotFoundError: [Errno 2] No such file or directory: 'src/Logic/img/demo.mp4'
2020-04-28 15:48:44,854 - Logic.Commands - INFO - User 383327735: send /start command;
2020-04-28 15:48:45,856 - telegram.ext.dispatcher - ERROR - No error handlers are registered, logging exception.
Traceback (most recent call last):
  File "/var/www/venv/lib64/python3.6/site-packages/telegram/ext/dispatcher.py", line 343, in process_update
    handler.handle_update(update, self, check, context)
  File "/var/www/venv/lib64/python3.6/site-packages/telegram/ext/handler.py", line 117, in handle_update
    return self.callback(update, context)
  File "/var/www/parent-bot/src/Logic/Commands.py", line 50, in demo
    video=open("src/Logic/img/demo.mp4", "rb"),
FileNotFoundError: [Errno 2] No such file or directory: 'src/Logic/img/demo.mp4'
2020-04-28 15:48:51,479 - Logic.Commands - INFO - User 383327735: send /start command;
2020-04-28 15:49:57,444 - Logic.Payment - INFO - User 383327735: genetare link to subscribe - http://tinyurl.com/ybyn3wad;
2020-04-28 15:52:37,405 - Logic.Commands - INFO - User 383327735: send /start command;
2020-04-28 15:52:39,037 - Logic.Payment - INFO - User 383327735: genetare link to subscribe - http://tinyurl.com/ydbraf98;
2020-04-28 15:53:02,821 - Logic.Commands - INFO - User 383327735: send /start command;
2020-04-28 15:54:59,469 - Logic.Commands - INFO - User 383327735: send /start command;
2020-04-28 15:57:12,310 - Logic.Payment - INFO - User 383327735: genetare link to subscribe - http://tinyurl.com/y9pbph9t;
2020-04-28 15:57:13,588 - Logic.Commands - INFO - User 383327735: send /start command;
2020-04-28 15:57:14,779 - Logic.Payment - INFO - User 383327735: genetare link to subscribe - http://tinyurl.com/y9q727es;
2020-04-28 15:57:42,303 - Logic.Commands - INFO - User 383327735: send /start command;
2020-04-28 16:01:34,376 - Logic.Commands - INFO - User 383327735: send /start command;
2020-04-28 16:01:35,565 - Logic.Payment - INFO - User 383327735: genetare link to subscribe - http://tinyurl.com/y7sphkxs;
2020-04-28 16:02:56,431 - Logic.Commands - INFO - User 383327735: send /start command;
2020-04-28 16:02:57,606 - Logic.Payment - INFO - User 383327735: genetare link to subscribe - http://tinyurl.com/y9r97yua;
2020-04-28 16:04:49,963 - Logic.Commands - INFO - User 383327735: send /start command;
2020-04-28 16:04:51,349 - Logic.Payment - INFO - User 383327735: genetare link to subscribe - http://tinyurl.com/yaqwqmsd;
2020-04-28 16:05:11,417 - Logic.Commands - INFO - User 383327735: send /start command;
2020-04-28 16:10:12,208 - Logic.Commands - INFO - User 383327735: send /start command;
2020-04-28 16:10:39,296 - Logic.Commands - INFO - User 383327735: send /start command;
2020-04-28 16:10:40,466 - Logic.Payment - INFO - User 383327735: genetare link to subscribe - http://tinyurl.com/yd7fheqy;
2020-04-28 16:40:48,545 - Logic.Commands - INFO - User 384341805: send /start command;
2020-04-28 16:40:49,799 - telegram.ext.dispatcher - ERROR - No error handlers are registered, logging exception.
Traceback (most recent call last):
  File "/var/www/venv/lib64/python3.6/site-packages/telegram/ext/dispatcher.py", line 343, in process_update
    handler.handle_update(update, self, check, context)
  File "/var/www/venv/lib64/python3.6/site-packages/telegram/ext/handler.py", line 117, in handle_update
    return self.callback(update, context)
  File "/var/www/parent-bot/src/Logic/Commands.py", line 50, in demo
    video=open("src/Logic/img/demo.mp4", "rb"),
FileNotFoundError: [Errno 2] No such file or directory: 'src/Logic/img/demo.mp4'
